Workbook

Sheet Input Costs
A1: COST INPUTS DATABASE
A2: Last Updated: | B2: =TODAY() -> 46062
A3: Currency Base: | B3: INR
A5: EXCHANGE RATES
A6: USD/INR | B6: 91.59
A7: EUR/INR | B7: 108.44
A8: CAD/INR | B8: 66.88
A9: GBP/INR | B9: 125.06
A11: CONVERTING COSTS (per MT) | B11: INR | C11: USD | D11: EUR | E11: CAD | F11: GBP
A12: Direct Labor | B12: 6500 | C12: =B12/$B$6 -> 70.968446 | D12: =B12/$B$7 -> 59.940981 | E12: =B12/$B$8 -> 97.188995 | F12: =B12/$B$9 -> 51.975052
A13: Power/Electricity | B13: 2500 | C13: =B13/$B$6 -> 27.295556 | D13: =B13/$B$7 -> 23.054224 | E13: =B13/$B$8 -> 37.380383 | F13: =B13/$B$9 -> 19.990405
A14: Cores | B14: 3500 | C14: =B14/$B$6 -> 38.213779 | D14: =B14/$B$7 -> 32.275913 | E14: =B14/$B$8 -> 52.332536 | F14: =B14/$B$9 -> 27.986566
A15: Glue/Adhesive | B15: 800 | C15: =B15/$B$6 -> 8.734578 | D15: =B15/$B$7 -> 7.3773515 | E15: =B15/$B$8 -> 11.961722 | F15: =B15/$B$9 -> 6.3969295
A16: Machine Maintenance | B16: 2500 | C16: =B16/$B$6 -> 27.295556 | D16: =B16/$B$7 -> 23.054224 | E16: =B16/$B$8 -> 37.380383 | F16: =B16/$B$9 -> 19.990405
A17: Consumables (blades, etc.) | B17: 1000 | C17: =B17/$B$6 -> 10.918223 | D17: =B17/$B$7 -> 9.2216894 | E17: =B17/$B$8 -> 14.952153 | F17: =B17/$B$9 -> 7.9961618
A18: TOTAL CONVERTING/MT | B18: =SUM(B12:B17) -> 16800 | C18: =B18/$B$6 -> 183.42614 | D18: =B18/$B$7 -> 154.92438 | E18: =B18/$B$8 -> 251.19617 | F18: =B18/$B$9 -> 134.33552
A20: PACKAGING MATERIALS | B20: INR | C20: Unit
A21: Printed Poly Film | B21: 220 | C21: per kg
A22: Plain Poly Film | B22: 170 | C22: per kg
A23: Paper Wrap | B23: 120 | C23: per kg
A24: Average Carton Cost | B24: 40 | C24: each
A25: Tape per Carton | B25: 3 | C25: each
A26: Labels per Carton | B26: 2 | C26: each
A27: Pallet Cost (wooden) | B27: 500 | C27: each
A28: Stretch Wrap per Pallet | B28: 120 | C28: each
A29: Strapping per Pallet | B29: 50 | C29: each
A31: FILM USAGE (grams per unit) | B31: Grams
A32: Toilet Roll (single wrap) | B32: 3
A33: Toilet Roll (multipack) | B33: 8
A34: Kitchen Towel (AFH) | B34: 12
A35: Napkin Pack | B35: 5
A37: OVERHEAD COSTS (Monthly) | B37: INR
A38: Factory Rent/Lease | B38: 150000
A39: Admin Salaries | B39: 200000
A40: Utilities (non-production) | B40: 50000
A41: Quality Control | B41: 75000
A42: Insurance | B42: 40000
A43: Depreciation | B43: 100000
A44: Other Overhead | B44: 50000
A45: TOTAL MONTHLY OVERHEAD | B45: =SUM(B38:B44) -> 665000
...

Sheet Input Reels
A1: Product_Description | B1: Reel_Code | C1: Supplier | D1: Ply | E1: GSM_Per_Ply | F1: Total_GSM | G1: Virgin_Pct | H1: Wet_Strength | I1: Color | J1: Softness | K1: Width_mm | L1: Dia_mm | M1: Price_INR_MT | N1: Price_USD_MT | O1: Lead_Days | P1: MOQ_MT | Q1: Last_Updated | R1: Notes
A2: VIRGIN WHITE SOFTNESS STANDARD | B2: R-1P-13-V | C2: Supplier A | D2: 1 | E2: 13 | F2: =D2*E2 -> 13 | G2: 1 | H2: No | I2: White | J2: Standard | K2: 2800 | L2: 1500 | M2: 112000 | N2: =M2/'Input Costs'!$B$6 -> 1222.8409 | O2: 21 | P2: 5 | Q2: =TODAY() -> 46062 | R2: Ultra light tissue
B3: R-1P-14-V | C3: Supplier A | D3: 1 | E3: 14 | F3: =D3*E3 -> 14 | G3: 1 | H3: No | I3: White | J3: Standard | K3: 2800 | L3: 1500 | M3: 108000 | N3: =M3/'Input Costs'!$B$6 -> 1179.168 | O3: 21 | P3: 5 | Q3: =TODAY() -> 46062 | R3: Light facial tissue
B4: R-1P-15-V | C4: Supplier A | D4: 1 | E4: 15 | F4: =D4*E4 -> 15 | G4: 1 | H4: No | I4: White | J4: Standard | K4: 2800 | L4: 1500 | M4: 105000 | N4: =M4/'Input Costs'!$B$6 -> 1146.4134 | O4: 21 | P4: 5 | Q4: =TODAY() -> 46062 | R4: Standard facial
B5: R-1P-16-V | C5: Supplier A | D5: 1 | E5: 16 | F5: =D5*E5 -> 16 | G5: 1 | H5: No | I5: White | J5: Standard | K5: 2800 | L5: 1500 | M5: 103000 | N5: =M5/'Input Costs'!$B$6 -> 1124.5769 | O5: 21 | P5: 5 | Q5: =TODAY() -> 46062 | R5: Light toilet tissue
B6: R-1P-17-V | C6: Supplier A | D6: 1 | E6: 17 | F6: =D6*E6 -> 17 | G6: 1 | H6: No | I6: White | J6: Standard | K6: 2800 | L6: 1500 | M6: 102000 | N6: =M6/'Input Costs'!$B$6 -> 1113.6587 | O6: 21 | P6: 5 | Q6: =TODAY() -> 46062 | R6: Standard toilet
B7: R-1P-18-V | C7: Supplier A | D7: 1 | E7: 18 | F7: =D7*E7 -> 18 | G7: 1 | H7: No | I7: White | J7: Standard | K7: 2800 | L7: 1500 | M7: 100000 | N7: =M7/'Input Costs'!$B$6 -> 1091.8223 | O7: 21 | P7: 5 | Q7: =TODAY() -> 46062 | R7: Standard napkin
B8: R-1P-19-V | C8: Supplier A | D8: 1 | E8: 19 | F8: =D8*E8 -> 19 | G8: 1 | H8: No | I8: White | J8: Standard | K8: 2800 | L8: 1500 | M8: 98000 | N8: =M8/'Input Costs'!$B$6 -> 1069.9858 | O8: 21 | P8: 5 | Q8: =TODAY() -> 46062 | R8: Medium weight
B9: R-1P-20-V | C9: Supplier A | D9: 1 | E9: 20 | F9: =D9*E9 -> 20 | G9: 1 | H9: No | I9: White | J9: Standard | K9: 2800 | L9: 1500 | M9: 97000 | N9: =M9/'Input Costs'!$B$6 -> 1059.0676 | O9: 21 | P9: 5 | Q9: =TODAY() -> 46062 | R9: Kitchen towel base
B10: R-1P-21-V | C10: Supplier A | D10: 1 | E10: 21 | F10: =D10*E10 -> 21 | G10: 1 | H10: No | I10: White | J10: Standard | K10: 2800 | L10: 1500 | M10: 96000 | N10: =M10/'Input Costs'!$B$6 -> 1048.1494 | O10: 21 | P10: 5 | Q10: =TODAY() -> 46062 | R10: Medium KT
B11: R-1P-22-V | C11: Supplier A | D11: 1 | E11: 22 | F11: =D11*E11 -> 22 | G11: 1 | H11: No | I11: White | J11: Standard | K11: 2800 | L11: 1500 | M11: 95000 | N11: =M11/'Input Costs'!$B$6 -> 1037.2311 | O11: 21 | P11: 5 | Q11: =TODAY() -> 46062 | R11: Standard KT
B12: R-1P-23-V | C12: Supplier A | D12: 1 | E12: 23 | F12: =D12*E12 -> 23 | G12: 1 | H12: No | I12: White | J12: Standard | K12: 2800 | L12: 1500 | M12: 94000 | N12: =M12/'Input Costs'!$B$6 -> 1026.3129 | O12: 21 | P12: 5 | Q12: =TODAY() -> 46062 | R12: Heavy KT
B13: R-1P-24-V | C13: Supplier A | D13: 1 | E13: 24 | F13: =D13*E13 -> 24 | G13: 1 | H13: No | I13: White | J13: Standard | K13: 2800 | L13: 1500 | M13: 93000 | N13: =M13/'Input Costs'!$B$6 -> 1015.3947 | O13: 21 | P13: 5 | Q13: =TODAY() -> 46062 | R13: Industrial base
B14: R-1P-25-V | C14: Supplier A | D14: 1 | E14: 25 | F14: =D14*E14 -> 25 | G14: 1 | H14: No | I14: White | J14: Standard | K14: 2800 | L14: 1500 | M14: 92000 | N14: =M14/'Input Costs'!$B$6 -> 1004.4765 | O14: 21 | P14: 5 | Q14: =TODAY() -> 46062 | R14: Heavy duty
... B16: R-1P-30-V | C16: Supplier A | D16: 1 | E16: 30 | F16: =D16*E16 -> 30 | G16: 1 | H16: No | I16: White | J16: Standard | K16: 2800 | L16: 1500 | M16: 88000 | N16: =M16/'Input Costs'!$B$6 -> 960.80358 | O16: 21 | P16: 5 | Q16: =TODAY() -> 46062 | R16: Wiper base
A17: VIRGIN WHITE SOFTNESS PREMIUM | B17: R-1P-13-VP | C17: Supplier A | D17: 1 | E17: 13 | F17: =D17*E17 -> 13 | G17: 1 | H17: No | I17: White | J17: Premium | K17: 2800 | L17: 1500 | M17: 125000 | N17: =M17/'Input Costs'!$B$6 -> 1364.7778 | O17: 25 | P17: 5 | Q17: =TODAY() -> 46062 | R17: Premium facial
B18: R-1P-14-VP | C18: Supplier A | D18: 1 | E18: 14 | F18: =D18*E18 -> 14 | G18: 1 | H18: No | I18: White | J18: Premium | K18: 2800 | L18: 1500 | M18: 122000 | N18: =M18/'Input Costs'!$B$6 -> 1332.0231 | O18: 25 | P18: 5 | Q18: =TODAY() -> 46062 | R18: Premium facial
B19: R-1P-15-VP | C19: Supplier A | D19: 1 | E19: 15 | F19: =D19*E19 -> 15 | G19: 1 | H19: No | I19: White | J19: Premium | K19: 2800 | L19: 1500 | M19: 118000 | N19: =M19/'Input Costs'!$B$6 -> 1288.3503 | O19: 25 | P19: 5 | Q19: =TODAY() -> 46062 | R19: Premium toilet
B20: R-1P-16-VP | C20: Supplier A | D20: 1 | E20: 16 | F20: =D20*E20 -> 16 | G20: 1 | H20: No | I20: White | J20: Premium | K20: 2800 | L20: 1500 | M20: 116000 | N20: =M20/'Input Costs'!$B$6 -> 1266.5138 | O20: 25 | P20: 5 | Q20: =TODAY() -> 46062 | R20: Premium toilet
B21: R-1P-17-VP | C21: Supplier A | D21: 1 | E21: 17 | F21: =D21*E21 -> 17 | G21: 1 | H21: No | I21: White | J21: Premium | K21: 2800 | L21: 1500 | M21: 115000 | N21: =M21/'Input Costs'!$B$6 -> 1255.5956 | O21: 25 | P21: 5 | Q21: =TODAY() -> 46062 | R21: Luxury toilet
B22: R-1P-18-VP | C22: Supplier A | D22: 1 | E22: 18 | F22: =D22*E22 -> 18 | G22: 1 | H22: No | I22: White | J22: Premium | K22: 2800 | L22: 1500 | M22: 113000 | N22: =M22/'Input Costs'!$B$6 -> 1233.7591 | O22: 25 | P22: 5 | Q22: =TODAY() -> 46062 | R22: Premium napkin
B23: R-1P-20-VP | C23: Supplier A | D23: 1 | E23: 20 | F23: =D23*E23 -> 20 | G23: 1 | H23: No | I23: White | J23: Premium | K23: 2800 | L23: 1500 | M23: 110000 | N23: =M23/'Input Costs'!$B$6 -> 1201.0045 | O23: 25 | P23: 5 | Q23: =TODAY() -> 46062 | R23: Premium KT
B24: R-1P-22-VP | C24: Supplier A | D24: 1 | E24: 22 | F24: =D24*E24 -> 22 | G24: 1 | H24: No | I24: White | J24: Premium | K24: 2800 | L24: 1500 | M24: 108000 | N24: =M24/'Input Costs'!$B$6 -> 1179.168 | O24: 25 | P24: 5 | Q24: =TODAY() -> 46062 | R24: Premium KT
A25: VIRGIN WHITE SOFTNESS ECONOMY | B25: R-1P-15-VE | C25: Supplier A | D25: 1 | E25: 15 | F25: =D25*E25 -> 15 | G25: 1 | H25: No | I25: White | J25: Economy | K25: 2800 | L25: 1500 | M25: 98000 | N25: =M25/'Input Costs'!$B$6 -> 1069.9858 | O25: 21 | P25: 10 | Q25: =TODAY() -> 46062 | R25: Budget toilet
B26: R-1P-17-VE | C26: Supplier A | D26: 1 | E26: 17 | F26: =D26*E26 -> 17 | G26: 1 | H26: No | I26: White | J26: Economy | K26: 2800 | L26: 1500 | M26: 95000 | N26: =M26/'Input Costs'!$B$6 -> 1037.2311 | O26: 21 | P26: 10 | Q26: =TODAY() -> 46062 | R26: Budget toilet
B27: R-1P-18-VE | C27: Supplier A | D27: 1 | E27: 18 | F27: =D27*E27 -> 18 | G27: 1 | H27: No | I27: White | J27: Economy | K27: 2800 | L27: 1500 | M27: 93000 | N27: =M27/'Input Costs'!$B$6 -> 1015.3947 | O27: 21 | P27: 10 | Q27: =TODAY() -> 46062 | R27: Budget napkin
B28: R-1P-20-VE | C28: Supplier A | D28: 1 | E28: 20 | F28: =D28*E28 -> 20 | G28: 1 | H28: No | I28: White | J28: Economy | K28: 2800 | L28: 1500 | M28: 90000 | N28: =M28/'Input Costs'!$B$6 -> 982.64003 | O28: 21 | P28: 10 | Q28: =TODAY() -> 46062 | R28: Budget KT
B29: R-1P-22-VE | C29: Supplier A | D29: 1 | E29: 22 | F29: =D29*E29 -> 22 | G29: 1 | H29: No | I29: White | J29: Economy | K29: 2800 | L29: 1500 | M29: 88000 | N29: =M29/'Input Costs'!$B$6 -> 960.80358 | O29: 21 | P29: 10 | Q29: =TODAY() -> 46062 | R29: Budget KT
A30: MIXED FIBER WHITE (VIRGIN + RECYCLED) | B30: R-1P-15-M80 | C30: Supplier A | D30: 1 | E30: 15 | F30: =D30*E30 -> 15 | G30: 0.8 | H30: No | I30: White | J30: Standard | K30: 2800 | L30: 1500 | M30: 95000 | N30: =M30/'Input Costs'!$B$6 -> 1037.2311 | O30: 21 | P30: 5 | Q30: =TODAY() -> 46062 | R30: 80% virgin blend
B31: R-1P-17-M80 | C31: Supplier A | D31: 1 | E31: 17 | F31: =D31*E31 -> 17 | G31: 0.8 | H31: No | I31: White | J31: Standard | K31: 2800 | L31: 1500 | M31: 93000 | N31: =M31/'Input Costs'!$B$6 -> 1015.3947 | O31: 21 | P31: 5 | Q31: =TODAY() -> 46062 | R31: 80% virgin blend
B32: R-1P-18-M80 | C32: Supplier A | D32: 1 | E32: 18 | F32: =D32*E32 -> 18 | G32: 0.8 | H32: No | I32: White | J32: Standard | K32: 2800 | L32: 1500 | M32: 91000 | N32: =M32/'Input Costs'!$B$6 -> 993.55825 | O32: 21 | P32: 5 | Q32: =TODAY() -> 46062 | R32: 80% virgin blend
B33: R-1P-20-M80 | C33: Supplier A | D33: 1 | E33: 20 | F33: =D33*E33 -> 20 | G33: 0.8 | H33: No | I33: White | J33: Standard | K33: 2800 | L33: 1500 | M33: 89000 | N33: =M33/'Input Costs'!$B$6 -> 971.7218 | O33: 21 | P33: 5 | Q33: =TODAY() -> 46062 | R33: 80% virgin blend
B34: R-1P-22-M80 | C34: Supplier A | D34: 1 | E34: 22 | F34: =D34*E34 -> 22 | G34: 0.8 | H34: No | I34: White | J34: Standard | K34: 2800 | L34: 1500 | M34: 87000 | N34: =M34/'Input Costs'!$B$6 -> 949.88536 | O34: 21 | P34: 5 | Q34: =TODAY() -> 46062 | R34: 80% virgin blend
B35: R-1P-15-M70 | C35: Supplier A | D35: 1 | E35: 15 | F35: =D35*E35 -> 15 | G35: 0.7 | H35: No | I35: White | J35: Standard | K35: 2800 | L35: 1500 | M35: 90000 | N35: =M35/'Input Costs'!$B$6 -> 982.64003 | O35: 21 | P35: 5 | Q35: =TODAY() -> 46062 | R35: 70% virgin blend
B36: R-1P-17-M70 | C36: Supplier A | D36: 1 | E36: 17 | F36: =D36*E36 -> 17 | G36: 0.7 | H36: No | I36: White | J36: Standard | K36: 2800 | L36: 1500 | M36: 88000 | N36: =M36/'Input Costs'!$B$6 -> 960.80358 | O36: 21 | P36: 5 | Q36: =TODAY() -> 46062 | R36: 70% virgin blend
B37: R-1P-18-M70 | C37: Supplier A | D37: 1 | E37: 18 | F37: =D37*E37 -> 18 | G37: 0.7 | H37: No | I37: White | J37: Standard | K37: 2800 | L37: 1500 | M37: 86000 | N37: =M37/'Input Costs'!$B$6 -> 938.96714 | O37: 21 | P37: 5 | Q37: =TODAY() -> 46062 | R37: 70% virgin blend
B38: R-1P-20-M70 | C38: Supplier A | D38: 1 | E38: 20 | F38: =D38*E38 -> 20 | G38: 0.7 | H38: No | I38: White | J38: Standard | K38: 2800 | L38: 1500 | M38: 84000 | N38: =M38/'Input Costs'!$B$6 -> 917.13069 | O38: 21 | P38: 5 | Q38: =TODAY() -> 46062 | R38: 70% virgin blend
B39: R-1P-22-M70 | C39: Supplier A | D39: 1 | E39: 22 | F39: =D39*E39 -> 22 | G39: 0.7 | H39: No | I39: White | J39: Standard | K39: 2800 | L39: 1500 | M39: 82000 | N39: =M39/'Input Costs'!$B$6 -> 895.29425 | O39: 21 | P39: 5 | Q39: =TODAY() -> 46062 | R39: 70% virgin blend
B40: R-1P-15-M50 | C40: Supplier A | D40: 1 | E40: 15 | F40: =D40*E40 -> 15 | G40: 0.5 | H40: No | I40: White | J40: Standard | K40: 2800 | L40: 1500 | M40: 82000 | N40: =M40/'Input Costs'!$B$6 -> 895.29425 | O40: 21 | P40: 5 | Q40: =TODAY() -> 46062 | R40: 50% virgin blend
B41: R-1P-17-M50 | C41: Supplier A | D41: 1 | E41: 17 | F41: =D41*E41 -> 17 | G41: 0.5 | H41: No | I41: White | J41: Standard | K41: 2800 | L41: 1500 | M41: 80000 | N41: =M41/'Input Costs'!$B$6 -> 873.4578 | O41: 21 | P41: 5 | Q41: =TODAY() -> 46062 | R41: 50% virgin blend
...

Sheet Input Products
A1: Product_Description | B1: Product_Code | C1: Product_Name | D1: Category | E1: Ply | F1: GSM_Per_Ply | G1: Sheet_Length_mm | H1: Sheet_Width_mm | I1: Sheet_Area_m2 | J1: Sheets_Per_Unit | K1: Core_Weight_g | L1: Core_ID_mm | M1: Roll_Dia_mm | N1: Wet_Strength | O1: Color | P1: Emboss | Q1: Print | R1: Wrap_Type | S1: Units_Per_Carton | T1: Cartons_Per_Pallet | U1: Pallets_Per_40HC | V1: Matched_Reel_Code | W1: Certification
A2: TOILET ROLLS
A3: 2-PLY STANDARD VIRGIN | B3: TT-2P-100-S | C3: Toilet Roll 2P 100Sht Std | D3: TT | E3: 2 | F3: 17 | G3: 100 | H3: 114 | I3: =G3*H3/1000000 -> 0.0114 | J3: 100 | K3: 6 | L3: 40 | M3: 85 | N3: No | O3: White | P3: Standard | Q3: No | R3: Printed | S3: 96 | T3: 72 | U3: 20 | V3: R-1P-17-V | W3: None
B4: TT-2P-150-S | C4: Toilet Roll 2P 150Sht Std | D4: TT | E4: 2 | F4: 17 | G4: 100 | H4: 114 | I4: =G4*H4/1000000 -> 0.0114 | J4: 150 | K4: 7 | L4: 40 | M4: 95 | N4: No | O4: White | P4: Standard | Q4: No | R4: Printed | S4: 64 | T4: 64 | U4: 20 | V4: R-1P-17-V | W4: None
B5: TT-2P-180-S | C5: Toilet Roll 2P 180Sht Std | D5: TT | E5: 2 | F5: 17 | G5: 100 | H5: 114 | I5: =G5*H5/1000000 -> 0.0114 | J5: 180 | K5: 8 | L5: 40 | M5: 100 | N5: No | O5: White | P5: Standard | Q5: No | R5: Printed | S5: 56 | T5: 60 | U5: 20 | V5: R-1P-17-V | W5: None
B6: TT-2P-200-S | C6: Toilet Roll 2P 200Sht Std | D6: TT | E6: 2 | F6: 17 | G6: 100 | H6: 114 | I6: =G6*H6/1000000 -> 0.0114 | J6: 200 | K6: 8 | L6: 40 | M6: 105 | N6: No | O6: White | P6: Standard | Q6: No | R6: Printed | S6: 48 | T6: 60 | U6: 20 | V6: R-1P-17-V | W6: None
B7: TT-2P-220-S | C7: Toilet Roll 2P 220Sht Std | D7: TT | E7: 2 | F7: 17 | G7: 100 | H7: 114 | I7: =G7*H7/1000000 -> 0.0114 | J7: 220 | K7: 9 | L7: 40 | M7: 108 | N7: No | O7: White | P7: Standard | Q7: No | R7: Printed | S7: 48 | T7: 56 | U7: 20 | V7: R-1P-17-V | W7: None
B8: TT-2P-250-S | C8: Toilet Roll 2P 250Sht Std | D8: TT | E8: 2 | F8: 17 | G8: 100 | H8: 114 | I8: =G8*H8/1000000 -> 0.0114 | J8: 250 | K8: 9 | L8: 40 | M8: 112 | N8: No | O8: White | P8: Standard | Q8: No | R8: Printed | S8: 40 | T8: 56 | U8: 20 | V8: R-1P-17-V | W8: None
B9: TT-2P-300-S | C9: Toilet Roll 2P 300Sht Std | D9: TT | E9: 2 | F9: 17 | G9: 100 | H9: 114 | I9: =G9*H9/1000000 -> 0.0114 | J9: 300 | K9: 10 | L9: 40 | M9: 120 | N9: No | O9: White | P9: Standard | Q9: No | R9: Printed | S9: 36 | T9: 56 | U9: 20 | V9: R-1P-17-V | W9: None
B10: TT-2P-350-S | C10: Toilet Roll 2P 350Sht Std | D10: TT | E10: 2 | F10: 17 | G10: 100 | H10: 114 | I10: =G10*H10/1000000 -> 0.0114 | J10: 350 | K10: 11 | L10: 40 | M10: 128 | N10: No | O10: White | P10: Standard | Q10: No | R10: Printed | S10: 32 | T10: 52 | U10: 20 | V10: R-1P-17-V | W10: None
B11: TT-2P-400-S | C11: Toilet Roll 2P 400Sht Std | D11: TT | E11: 2 | F11: 17 | G11: 100 | H11: 114 | I11: =G11*H11/1000000 -> 0.0114 | J11: 400 | K11: 12 | L11: 40 | M11: 135 | N11: No | O11: White | P11: Standard | Q11: No | R11: Printed | S11: 28 | T11: 48 | U11: 20 | V11: R-1P-17-V | W11: None
B12: TT-2P-500-S | C12: Toilet Roll 2P 500Sht Std | D12: TT | E12: 2 | F12: 17 | G12: 100 | H12: 114 | I12: =G12*H12/1000000 -> 0.0114 | J12: 500 | K12: 12 | L12: 40 | M12: 145 | N12: No | O12: White | P12: Standard | Q12: No | R12: Printed | S12: 24 | T12: 48 | U12: 20 | V12: R-1P-17-V | W12: None
B13: TT-2P-600-S | C13: Toilet Roll 2P 600Sht Std | D13: TT | E13: 2 | F13: 17 | G13: 100 | H13: 114 | I13: =G13*H13/1000000 -> 0.0114 | J13: 600 | K13: 14 | L13: 40 | M13: 155 | N13: No | O13: White | P13: Standard | Q13: No | R13: Printed | S13: 20 | T13: 44 | U13: 20 | V13: R-1P-17-V | W13: None
B14: TT-2P-800-S | C14: Toilet Roll 2P 800Sht Std | D14: TT | E14: 2 | F14: 17 | G14: 100 | H14: 114 | I14: =G14*H14/1000000 -> 0.0114 | J14: 800 | K14: 16 | L14: 40 | M14: 175 | N14: No | O14: White | P14: Standard | Q14: No | R14: Printed | S14: 16 | T14: 40 | U14: 20 | V14: R-1P-17-V | W14: None
B15: TT-2P-1000-S | C15: Toilet Roll 2P 1000Sht Std | D15: TT | E15: 2 | F15: 17 | G15: 100 | H15: 114 | I15: =G15*H15/1000000 -> 0.0114 | J15: 1000 | K15: 18 | L15: 40 | M15: 195 | N15: No | O15: White | P15: Standard | Q15: No | R15: Printed | S15: 12 | T15: 36 | U15: 20 | V15: R-1P-17-V | W15: None
A16: 2-PLY DEEP EMBOSS VIRGIN | B16: TT-2P-150-D | C16: Toilet Roll 2P 150Sht Deep | D16: TT | E16: 2 | F16: 17 | G16: 100 | H16: 114 | I16: =G16*H16/1000000 -> 0.0114 | J16: 150 | K16: 7 | L16: 40 | M16: 98 | N16: No | O16: White | P16: Deep | Q16: No | R16: Printed | S16: 64 | T16: 64 | U16: 20 | V16: R-1P-17-V | W16: None
B17: TT-2P-200-D | C17: Toilet Roll 2P 200Sht Deep | D17: TT | E17: 2 | F17: 17 | G17: 100 | H17: 114 | I17: =G17*H17/1000000 -> 0.0114 | J17: 200 | K17: 8 | L17: 40 | M17: 108 | N17: No | O17: White | P17: Deep | Q17: No | R17: Printed | S17: 48 | T17: 60 | U17: 20 | V17: R-1P-17-V | W17: None
B18: TT-2P-250-D | C18: Toilet Roll 2P 250Sht Deep | D18: TT | E18: 2 | F18: 17 | G18: 100 | H18: 114 | I18: =G18*H18/1000000 -> 0.0114 | J18: 250 | K18: 9 | L18: 40 | M18: 115 | N18: No | O18: White | P18: Deep | Q18: No | R18: Printed | S18: 40 | T18: 56 | U18: 20 | V18: R-1P-17-V | W18: None
B19: TT-2P-300-D | C19: Toilet Roll 2P 300Sht Deep | D19: TT | E19: 2 | F19: 17 | G19: 100 | H19: 114 | I19: =G19*H19/1000000 -> 0.0114 | J19: 300 | K19: 10 | L19: 40 | M19: 125 | N19: No | O19: White | P19: Deep | Q19: No | R19: Printed | S19: 36 | T19: 52 | U19: 20 | V19: R-1P-17-V | W19: None
B20: TT-2P-400-D | C20: Toilet Roll 2P 400Sht Deep | D20: TT | E20: 2 | F20: 17 | G20: 100 | H20: 114 | I20: =G20*H20/1000000 -> 0.0114 | J20: 400 | K20: 12 | L20: 40 | M20: 140 | N20: No | O20: White | P20: Deep | Q20: No | R20: Printed | S20: 28 | T20: 48 | U20: 20 | V20: R-1P-17-V | W20: None
B21: TT-2P-500-D | C21: Toilet Roll 2P 500Sht Deep | D21: TT | E21: 2 | F21: 17 | G21: 100 | H21: 114 | I21: =G21*H21/1000000 -> 0.0114 | J21: 500 | K21: 12 | L21: 40 | M21: 150 | N21: No | O21: White | P21: Deep | Q21: No | R21: Printed | S21: 24 | T21: 44 | U21: 20 | V21: R-1P-17-V | W21: None
A22: 2-PLY PREMIUM SOFTNESS | B22: TT-2P-150-P | C22: Toilet Roll 2P 150Sht Prem | D22: TT | E22: 2 | F22: 17 | G22: 100 | H22: 114 | I22: =G22*H22/1000000 -> 0.0114 | J22: 150 | K22: 7 | L22: 40 | M22: 98 | N22: No | O22: White | P22: Deep | Q22: No | R22: Printed | S22: 64 | T22: 60 | U22: 20 | V22: R-1P-17-VP | W22: None
B23: TT-2P-200-P | C23: Toilet Roll 2P 200Sht Prem | D23: TT | E23: 2 | F23: 17 | G23: 100 | H23: 114 | I23: =G23*H23/1000000 -> 0.0114 | J23: 200 | K23: 8 | L23: 40 | M23: 108 | N23: No | O23: White | P23: Deep | Q23: No | R23: Printed | S23: 48 | T23: 56 | U23: 20 | V23: R-1P-17-VP | W23: None
B24: TT-2P-250-P | C24: Toilet Roll 2P 250Sht Prem | D24: TT | E24: 2 | F24: 17 | G24: 100 | H24: 114 | I24: =G24*H24/1000000 -> 0.0114 | J24: 250 | K24: 9 | L24: 40 | M24: 115 | N24: No | O24: White | P24: Deep | Q24: No | R24: Printed | S24: 40 | T24: 52 | U24: 20 | V24: R-1P-17-VP | W24: None
B25: TT-2P-300-P | C25: Toilet Roll 2P 300Sht Prem | D25: TT | E25: 2 | F25: 17 | G25: 100 | H25: 114 | I25: =G25*H25/1000000 -> 0.0114 | J25: 300 | K25: 10 | L25: 40 | M25: 125 | N25: No | O25: White | P25: Deep | Q25: No | R25: Printed | S25: 36 | T25: 48 | U25: 20 | V25: R-1P-17-VP | W25: None
B26: TT-2P-400-P | C26: Toilet Roll 2P 400Sht Prem | D26: TT | E26: 2 | F26: 17 | G26: 100 | H26: 114 | I26: =G26*H26/1000000 -> 0.0114 | J26: 400 | K26: 12 | L26: 40 | M26: 140 | N26: No | O26: White | P26: Deep | Q26: No | R26: Printed | S26: 28 | T26: 44 | U26: 20 | V26: R-1P-17-VP | W26: None
B27: TT-2P-500-P | C27: Toilet Roll 2P 500Sht Prem | D27: TT | E27: 2 | F27: 17 | G27: 100 | H27: 114 | I27: =G27*H27/1000000 -> 0.0114 | J27: 500 | K27: 12 | L27: 40 | M27: 150 | N27: No | O27: White | P27: Deep | Q27: No | R27: Printed | S27: 24 | T27: 40 | U27: 20 | V27: R-1P-17-VP | W27: None
A28: 2-PLY ECONOMY (MIXED FIBER) | B28: TT-2P-150-E | C28: Toilet Roll 2P 150Sht Eco | D28: TT | E28: 2 | F28: 17 | G28: 100 | H28: 114 | I28: =G28*H28/1000000 -> 0.0114 | J28: 150 | K28: 7 | L28: 40 | M28: 95 | N28: No | O28: White | P28: Light | Q28: No | R28: Plain | S28: 64 | T28: 64 | U28: 20 | V28: R-1P-17-M70 | W28: None
B29: TT-2P-200-E | C29: Toilet Roll 2P 200Sht Eco | D29: TT | E29: 2 | F29: 17 | G29: 100 | H29: 114 | I29: =G29*H29/1000000 -> 0.0114 | J29: 200 | K29: 8 | L29: 40 | M29: 105 | N29: No | O29: White | P29: Light | Q29: No | R29: Plain | S29: 48 | T29: 60 | U29: 20 | V29: R-1P-17-M70 | W29: None
B30: TT-2P-250-E | C30: Toilet Roll 2P 250Sht Eco | D30: TT | E30: 2 | F30: 17 | G30: 100 | H30: 114 | I30: =G30*H30/1000000 -> 0.0114 | J30: 250 | K30: 9 | L30: 40 | M30: 112 | N30: No | O30: White | P30: Light | Q30: No | R30: Plain | S30: 40 | T30: 56 | U30: 20 | V30: R-1P-17-M70 | W30: None
B31: TT-2P-300-E | C31: Toilet Roll 2P 300Sht Eco | D31: TT | E31: 2 | F31: 17 | G31: 100 | H31: 114 | I31: =G31*H31/1000000 -> 0.0114 | J31: 300 | K31: 10 | L31: 40 | M31: 120 | N31: No | O31: White | P31: Light | Q31: No | R31: Plain | S31: 36 | T31: 56 | U31: 20 | V31: R-1P-17-M70 | W31: None
B32: TT-2P-400-E | C32: Toilet Roll 2P 400Sht Eco | D32: TT | E32: 2 | F32: 17 | G32: 100 | H32: 114 | I32: =G32*H32/1000000 -> 0.0114 | J32: 400 | K32: 12 | L32: 40 | M32: 135 | N32: No | O32: White | P32: Light | Q32: No | R32: Plain | S32: 28 | T32: 48 | U32: 20 | V32: R-1P-17-M70 | W32: None
B33: TT-2P-500-E | C33: Toilet Roll 2P 500Sht Eco | D33: TT | E33: 2 | F33: 17 | G33: 100 | H33: 114 | I33: =G33*H33/1000000 -> 0.0114 | J33: 500 | K33: 12 | L33: 40 | M33: 145 | N33: No | O33: White | P33: Light | Q33: No | R33: Plain | S33: 24 | T33: 48 | U33: 20 | V33: R-1P-17-M70 | W33: None
B34: TT-2P-600-E | C34: Toilet Roll 2P 600Sht Eco | D34: TT | E34: 2 | F34: 17 | G34: 100 | H34: 114 | I34: =G34*H34/1000000 -> 0.0114 | J34: 600 | K34: 14 | L34: 40 | M34: 155 | N34: No | O34: White | P34: Light | Q34: No | R34: Plain | S34: 20 | T34: 44 | U34: 20 | V34: R-1P-17-M70 | W34: None
B35: TT-2P-200-E50 | C35: Toilet Roll 2P 200Sht Eco50 | D35: TT | E35: 2 | F35: 17 | G35: 100 | H35: 114 | I35: =G35*H35/1000000 -> 0.0114 | J35: 200 | K35: 8 | L35: 40 | M35: 105 | N35: No | O35: White | P35: Light | Q35: No | R35: Plain | S35: 48 | T35: 60 | U35: 20 | V35: R-1P-17-M50 | W35: None
B36: TT-2P-300-E50 | C36: Toilet Roll 2P 300Sht Eco50 | D36: TT | E36: 2 | F36: 17 | G36: 100 | H36: 114 | I36: =G36*H36/1000000 -> 0.0114 | J36: 300 | K36: 10 | L36: 40 | M36: 120 | N36: No | O36: White | P36: Light | Q36: No | R36: Plain | S36: 36 | T36: 56 | U36: 20 | V36: R-1P-17-M50 | W36: None
A37: 2-PLY RECYCLED | B37: TT-2P-200-R | C37: Toilet Roll 2P 200Sht Recy | D37: TT | E37: 2 | F37: 17 | G37: 100 | H37: 114 | I37: =G37*H37/1000000 -> 0.0114 | J37: 200 | K37: 8 | L37: 40 | M37: 105 | N37: No | O37: White | P37: Light | Q37: No | R37: Plain | S37: 48 | T37: 60 | U37: 20 | V37: R-1P-17-R | W37: None
B38: TT-2P-300-R | C38: Toilet Roll 2P 300Sht Recy | D38: TT | E38: 2 | F38: 17 | G38: 100 | H38: 114 | I38: =G38*H38/1000000 -> 0.0114 | J38: 300 | K38: 10 | L38: 40 | M38: 120 | N38: No | O38: White | P38: Light | Q38: No | R38: Plain | S38: 36 | T38: 56 | U38: 20 | V38: R-1P-17-R | W38: None
B39: TT-2P-400-R | C39: Toilet Roll 2P 400Sht Recy | D39: TT | E39: 2 | F39: 17 | G39: 100 | H39: 114 | I39: =G39*H39/1000000 -> 0.0114 | J39: 400 | K39: 12 | L39: 40 | M39: 135 | N39: No | O39: White | P39: Light | Q39: No | R39: Plain | S39: 28 | T39: 48 | U39: 20 | V39: R-1P-17-R | W39: None
B40: TT-2P-500-R | C40: Toilet Roll 2P 500Sht Recy | D40: TT | E40: 2 | F40: 17 | G40: 100 | H40: 114 | I40: =G40*H40/1000000 -> 0.0114 | J40: 500 | K40: 12 | L40: 40 | M40: 145 | N40: No | O40: White | P40: Light | Q40: No | R40: Plain | S40: 24 | T40: 48 | U40: 20 | V40: R-1P-17-R | W40: None
...

Sheet LookUp Value
A1: EMBOSS_TYPE | B1: MULTIPLIER | C1: DESCRIPTION
A2: None | B2: 1 | C2: No embossing
A3: Light | B3: 1.03 | C3: Simple pattern, high speed
A4: Standard | B4: 1.06 | C4: Typical emboss pattern
A5: Deep | B5: 1.1 | C5: Deep emboss, slower speed
A6: Micro | B6: 1.15 | C6: Micro perf/emboss, specialized
A9: PRINT_TYPE | B9: MULTIPLIER | C9: DESCRIPTION
A10: No | B10: 1 | C10: No print on tissue
A11: Yes | B11: 1.12 | C11: Printed tissue (any)
A14: WRAP_TYPE | B14: RATE_KEY | C14: DESCRIPTION
A15: Printed | B15: Printed | C15: Uses Film_Printed_Rate
A16: Plain | B16: Plain | C16: Uses Film_Plain_Rate
A17: Paper | B17: Paper | C17: Uses Paper_Wrap rate
A18: Poly | B18: Plain | C18: Generic poly, use plain rate
A19: None | B19: None | C19: No individual wrap
A22: CATEGORY | B22: FILM_GRAMS | C22: DESCRIPTION
A23: TT | B23: 3 | C23: Toilet tissue single roll
A24: KT | B24: 12 | C24: Kitchen towel roll
A25: NAP | B25: 5 | C25: Napkin pack
A28: CERTIFICATION | B28: COST_PER_MT | C28: DESCRIPTION
A29: None | B29: 0 | C29: No certification
A30: FSC | B30: 3000 | C30: FSC chain of custody
A31: PEFC | B31: 2500 | C31: PEFC certification
A32: Food | B32: 2000 | C32: Food contact compliance
A33: FSC+Food | B33: 5000 | C33: Both FSC and Food contact
A36: DESTINATION | B36: FREIGHT_USD | C36: TRANSIT_DAYS | D36: CURRENCY
A37: USA - East Coast | B37: 3500 | C37: 30 | D37: USD
A38: USA - West Coast | B38: 2800 | C38: 22 | D38: USD
A39: Canada - Vancouver | B39: 3000 | C39: 24 | D39: CAD
A40: Canada - Toronto | B40: 4000 | C40: 35 | D40: CAD
A41: Europe - Rotterdam | B41: 2200 | C41: 22 | D41: EUR
A42: Europe - Hamburg | B42: 2400 | C42: 24 | D42: EUR
A43: UK - Felixstowe | B43: 2600 | C43: 25 | D43: GBP
A44: Middle East - Dubai | B44: 1200 | C44: 8 | D44: USD
A45: Australia-Melbourne | B45: 2000 | C45: 18 | D45: USD
A48: CORE_ID_MM | B48: COST_INR | C48: DESCRIPTION
A49: 40 | B49: 2.5 | C49: Standard toilet roll core
A50: 76 | B50: 5 | C50: AFH/industrial core
A51: 0 | B51: 0 | C51: No core (napkins, folded)

Sheet Calc Products
A1: PRODUCT COST CALCULATOR
A3: SELECT PRODUCT: | B3: TT-2P-200-R
A5: PRODUCT SPECIFICATIONS | B5: (Auto-populated)[VlookUp]
A6: Product Name | B6: =IFERROR(VLOOKUP($B$3,'Input Products'!$B:$W,2,FALSE),"SelectProduct") -> Toilet Roll 2P 200Sht Recy
A7: Category | B7: =IFERROR(VLOOKUP($B$3,'Input Products'!$B:$W,3,FALSE),"") -> TT
A8: Ply | B8: =IFERROR(VLOOKUP($B$3,'Input Products'!$B:$W,4,FALSE),"") -> 2
A9: GSM per Ply | B9: =IFERROR(VLOOKUP($B$3,'Input Products'!$B:$W,5,FALSE),"") -> 17
A10: Total GSM | B10: =B8*B9 -> 34
A11: Sheet Length (mm) | B11: =IFERROR(VLOOKUP($B$3,'Input Products'!$B:$W,6,FALSE),"") -> 100
A12: Sheet Width (mm) | B12: =IFERROR(VLOOKUP($B$3,'Input Products'!$B:$W,7,FALSE),"") -> 114
A13: Sheet Area (m²) | B13: =IFERROR(VLOOKUP($B$3,'Input Products'!$B:$W,8,FALSE),"") -> 0.0114
A14: Sheets per Unit | B14: =IFERROR(VLOOKUP($B$3,'Input Products'!$B:$W,9,FALSE),"") -> 200
A15: Core Weight (g) | B15: =IFERROR(VLOOKUP($B$3,'Input Products'!$B:$W,10,FALSE),"") -> 8
A16: Core ID (mm) | B16: =IFERROR(VLOOKUP($B$3,'Input Products'!$B:$W,11,FALSE),"") -> 40
A17: Wet Strength Required | B17: =IFERROR(VLOOKUP($B$3,'Input Products'!$B:$W,13,FALSE),"") -> No
A18: Color | B18: =IFERROR(VLOOKUP($B$3,'Input Products'!$B:$W,14,FALSE),"") -> White
A19: Emboss Type | B19: =IFERROR(VLOOKUP($B$3,'Input Products'!$B:$W,15,FALSE),"") -> Light
A20: Print | B20: =IFERROR(VLOOKUP($B$3,'Input Products'!$B:$W,16,FALSE),"") -> No
A21: Wrap Type | B21: =IFERROR(VLOOKUP($B$3,'Input Products'!$B:$W,17,FALSE),"") -> Plain
A22: Units per Carton | B22: =IFERROR(VLOOKUP($B$3,'Input Products'!$B:$W,18,FALSE),"") -> 48
A23: Cartons per Pallet | B23: =IFERROR(VLOOKUP($B$3,'Input Products'!$B:$W,19,FALSE),"") -> 60
A24: Pallets per 40HC | B24: =IFERROR(VLOOKUP($B$3,'Input Products'!$B:$W,20,FALSE),"") -> 20
A25: Matched Reel Code | B25: =IFERROR(VLOOKUP($B$3,'Input Products'!$B:$W,21,FALSE),"") -> R-1P-17-R
A26: Certification | B26: =IFERROR(VLOOKUP($B$3,'Input Products'!$B:$W,22,FALSE),"") -> None
A29: PARENT REEL DATA
A30: Reel Code | B30: =B25 -> R-1P-17-R
A31: Reel Price (INR/MT) | B31: =IFERROR(VLOOKUP($B$30,'Input Reels'!$B:$M,12,FALSE),"NoReelMatch") -> 62000
A32: Reel Price (USD/MT) | B32: =IFERROR(B31/'Input Costs'!$B$6," ") -> 676.9298
A35: FIBER MASS CALCULATION | B35: Value | C35: Formula/Notes
A36: Gross Fiber per Unit (g) | B36: =IFERROR(B8*B9*B13*B14,"") -> 77.52 | C36: =Ply × GSM × Area × Sheets
A37: Loss Factor | B37: ='Input Costs'!B54 -> 1.055 | C37: From 'Input Costs'
A38: Net Fiber Needed (g) | B38: =IFERROR(B36*B37,"") -> 81.7836 | C38: Gross × Loss Factor
A39: Core Weight (g) | B39: =B15 -> 8 | C39: From product specs
A40: Total Unit Mass (g) | B40: =IFERROR(B38+B39,"") -> 89.7836 | C40: Fiber + Core
A41: Units per MT | B41: =1000000/B40 -> 11137.892 | C41: How many units from 1 MT
A43: COST CALCULATION | B43: INR per Unit | C43: USD per Unit
A45: 1. REEL/FIBER COST
A46: Reel Price (INR/MT) | B46: =B38 -> 81.7836 | C46: From Reel Lookup (Row 38)
A47: Fiber cost per unit | B47: =IFERROR((B37/1000000)*B46,"") -> 8.6281698e-05 | C47: =IFERROR(B47/'Input Costs'!$B$6," ") -> 9.4204278e-07
A49: 2. CORE COST
...

Sheet Calc Export
A1: EXPORT LANDED COST CALCULATOR
A3: INPUTS
A4: Product Code | B4: ='Calc Products'!B3 -> TT-2P-200-R
A5: Product Name | B5: ='Calc Products'!B6 -> Toilet Roll 2P 200Sht Recy
A6: Destination | B6: Canada - Vancouver
A7: Quantity (units) | B7: 100000
A8: Incoterm | B8: FOB
A10: SHIPMENT CALCULATION
A11: Units ordered | B11: =B7 -> 100000 | C11: From input above
A12: Units per carton | B12: ='Calc Products'!B22 -> 48 | C12: From CALC_Product
A13: Cartons needed | B13: =IFERROR(ROUNDUP(B11/B12,0),"") -> 2084 | C13: Rounded up
A14: Cartons per pallet | B14: ='Calc Products'!B23 -> 60 | C14: From CALC_Product
A15: Pallets needed | B15: =IFERROR(ROUNDUP(B13/B14,0),"") -> 35 | C15: Rounded up
A16: Pallets per 40HC | B16: ='Calc Products'!B24 -> 20 | C16: From CALC_Product
A17: Containers needed | B17: =IFERROR(ROUNDUP(B15/B16,0),"") -> 2 | C17: Rounded up
A18: Container utilization | B18: =IFERROR(B15/(B17*B16),"") -> 0.875 | C18: Format as %
A19: Actual units shipped | B19: =IFERROR(B13*B12,"") -> 100032 | C19: May differ due to rounding
A20: Excess units | B20: =IFERROR(B19-B11,"") -> 32 | C20: Extra units in shipment
A22: COST BUILDUP | B22: INR | C22: USD
A24: EX-WORKS VALUE
A25: Ex-works cost per unit | B25: ='Calc Products'!B85 -> 3.7668427 | C25: ='Calc Products'!C85 -> 0.052044469
A26: Total ex-works value | B26: =IFERROR(B25*B19,"") -> 376804.81 | C26: =IFERROR(C25*B19,"") -> 5206.1124
A28: LOCAL LOGISTICS
A29: Factory to port | B29: =IFERROR('Input Costs'!$B$58*B17,"") -> 70000 | C29: =IFERROR(B29/'Input Costs'!$B$6,"") -> 764.27558
A30: Port handling | B30: =IFERROR('Input Costs'!$B$59*B17,"") -> 50000 | C30: =IFERROR(B30/'Input Costs'!$B$6,"") -> 545.91113
A31: Documentation | B31: =IFERROR('Input Costs'!$B$60,"") -> 15000 | C31: =IFERROR(B31/'Input Costs'!$B$6,"") -> 163.77334
A32: Export customs | B32: =IFERROR('Input Costs'!$B$61,"") -> 10000 | C32: =IFERROR(B32/'Input Costs'!$B$6,"") -> 109.18223
A33: Certificates | B33: =IFERROR('Input Costs'!$B$62,"") -> 5000 | C33: =IFERROR(B33/'Input Costs'!$B$6,"") -> 54.591113
A34: Total local logistics | B34: =IFERROR(SUM(B29:B33),"") -> 150000 | C34: =IFERROR(SUM(C29:C33),"") -> 1637.7334
A36: FOB VALUE | B36: =IFERROR(B26+B34,"") -> 526804.81 | C36: =IFERROR(C26+C34,"") -> 6843.8457
A38: INTERNATIONAL FREIGHT
A39: Freight rate per 40HC (USD) | B39: =IFERROR(VLOOKUP(B6,'LookUp Value'!$A$37:$B$45,2,FALSE),"") -> 3000 | C39: (Same as B39)
A40: Freight rate per 40HC (INR) | B40: =IFERROR(B39*'Input Costs'!$B$6,"") -> 274770 | C40: =B39 -> 3000
A41: Total ocean freight | B41: =IFERROR(B40*B17,"") -> 549540 | C41: =IFERROR(C40*B17,"") -> 6000
A42: Marine insurance | B42: =IFERROR(B36*'Input Costs'!$B$76,"") -> 2107.2192 | C42: =IFERROR(C36*'Input Costs'!$B$76,"") -> 27.375383
A43: Total freight & insurance | B43: =IFERROR(B41+B42,"") -> 551647.22 | C43: =IFERROR(C41+C42,"") -> 6027.3754
A45: CIF VALUE | B45: =IFERROR(B36+B43,"") -> 1078452 | C45: =IFERROR(C36+C43,"") -> 12871.221
A47: DESTINATION COSTS (if DAP)
A48: Import duty estimate | B48: 0 | C48: 0
A49: Customs clearance | B49: 0 | C49: 0
...

Sheet Quote Summary
A1: COMPANY HEADER
A2: [YOUR COMPANY NAME]
A3: [Address Line 1]
A4: [City, State, PIN Code]
A5: [Phone: +91-XXXX-XXXXXX]
A6: [Email: sales@company.com]
A7: QUOTATION
A8: Quote Date: | B8: =TODAY() -> 46062
A9: Valid Until: | B9: =B8+30 -> 46092
A10: Quote Reference: | B10: ="Q-"&TEXT(B8,"YYMMDD")&"-"&LEFT('Calc Export'!$B$4,10) -> Q-260209- TT-2P-200
A11: CUSTOMER DETAILS
A12: Customer Name: | B12: [Type Customer Name Here]
A13: Contact Person: | B13: [Type Contact Person Here]
A14: Email: | B14: [Type Email Here]
A15: Phone: | B15: [Type Phone Here]
A16: Destination: | B16: ='Calc Export'!$B$6 -> Canada - Vancouver
A17: PRODUCT DETAILS
A18: Product Code: | B18: ='Calc Products'!$B$3 -> TT-2P-200-R
A19: Product Description: | B19: ='Calc Products'!$B$6 -> Toilet Roll 2P 200Sht Recy
A20: Ply: | B20: ='Calc Products'!$B$8 -> 2
A21: GSM (Total): | B21: ='Calc Products'!B10 -> 34
A22: Specifications: | B22: =B20&"-Ply, "&B21&" GSM Total" -> 2-Ply, 34 GSM Total
A23: Color: | B23: ='Calc Products'!$B$18 -> White
A24: Sheets per Unit: | B24: ='Calc Products'!B14 -> 200
A25: Emboss: | B25: ='Calc Products'!B19 -> Light
A26: Certification: | B26: ='Calc Products'!B26 -> None
A27: PACKAGING DETAILS
A28: Units per Carton: | B28: ='Calc Products'!$B$22 -> 48
A29: Cartons per Pallet: | B29: ='Calc Products'!$B$23 -> 60
A30: Pallets per 40'HC: | B30: ='Calc Products'!$B$24 -> 20
A31: Units per Pallet: | B31: =B28*B29 -> 2880
A32: Units per Container: | B32: =B31*B30 -> 57600
A33: ORDER QUANTITY
A34: Units Ordered: | B34: ='Calc Export'!$B$7 -> 100000
A35: Actual Units (shipped): | B35: ='Calc Export'!$B$19 -> 100032
A36: Cartons: | B36: ='Calc Export'!$B$13 -> 2084
A37: Pallets: | B37: ='Calc Export'!$B$15 -> 35
A38: 40'HC Containers: | B38: ='Calc Export'!$B$17 -> 2
A39: Container Utilization: | B39: ='Calc Export'!$B$18 -> 0.875 | C39: Format as %
A40: PRICING
...
